Traceback (most recent call last):
  File "/workspaces/abdou.github.io/osint_env/lib/python3.12/site-packages/sqlalchemy/engine/base.py", line 145, in __init__
    self._dbapi_connection = engine.raw_connection()
                             ^^^^^^^^^^^^^^^^^^^^^^^
  File "/workspaces/abdou.github.io/osint_env/lib/python3.12/site-packages/sqlalchemy/engine/base.py", line 3292, in raw_connection
    return self.pool.connect()
           ^^^^^^^^^^^^^^^^^^^
  File "/workspaces/abdou.github.io/osint_env/lib/python3.12/site-packages/sqlalchemy/pool/base.py", line 452, in connect
    return _ConnectionFairy._checkout(self)
           ^^^^^^^^^^^^^^^^^^^^^^^^^^^^^^^^
  File "/workspaces/abdou.github.io/osint_env/lib/python3.12/site-packages/sqlalchemy/pool/base.py", line 1269, in _checkout
    fairy = _ConnectionRecord.checkout(pool)
            ^^^^^^^^^^^^^^^^^^^^^^^^^^^^^^^^
  File "/workspaces/abdou.github.io/osint_env/lib/python3.12/site-packages/sqlalchemy/pool/base.py", line 716, in checkout
    rec = pool._do_get()
          ^^^^^^^^^^^^^^
  File "/workspaces/abdou.github.io/osint_env/lib/python3.12/site-packages/sqlalchemy/pool/impl.py", line 169, in _do_get
    with util.safe_reraise():
  File "/workspaces/abdou.github.io/osint_env/lib/python3.12/site-packages/sqlalchemy/util/langhelpers.py", line 146, in __exit__
    raise exc_value.with_traceback(exc_tb)
  File "/workspaces/abdou.github.io/osint_env/lib/python3.12/site-packages/sqlalchemy/pool/impl.py", line 167, in _do_get
    return self._create_connection()
           ^^^^^^^^^^^^^^^^^^^^^^^^^
  File "/workspaces/abdou.github.io/osint_env/lib/python3.12/site-packages/sqlalchemy/pool/base.py", line 393, in _create_connection
    return _ConnectionRecord(self)
           ^^^^^^^^^^^^^^^^^^^^^^^
  File "/workspaces/abdou.github.io/osint_env/lib/python3.12/site-packages/sqlalchemy/pool/base.py", line 678, in __init__
    self.__connect()
  File "/workspaces/abdou.github.io/osint_env/lib/python3.12/site-packages/sqlalchemy/pool/base.py", line 902, in __connect
    with util.safe_reraise():
  File "/workspaces/abdou.github.io/osint_env/lib/python3.12/site-packages/sqlalchemy/util/langhelpers.py", line 146, in __exit__
    raise exc_value.with_traceback(exc_tb)
  File "/workspaces/abdou.github.io/osint_env/lib/python3.12/site-packages/sqlalchemy/pool/base.py", line 898, in __connect
    self.dbapi_connection = connection = pool._invoke_creator(self)
                                         ^^^^^^^^^^^^^^^^^^^^^^^^^^
  File "/workspaces/abdou.github.io/osint_env/lib/python3.12/site-packages/sqlalchemy/engine/create.py", line 637, in connect
    return dialect.connect(*cargs, **cparams)
           ^^^^^^^^^^^^^^^^^^^^^^^^^^^^^^^^^^
  File "/workspaces/abdou.github.io/osint_env/lib/python3.12/site-packages/sqlalchemy/engine/default.py", line 616, in connect
    return self.loaded_dbapi.connect(*cargs, **cparams)
           ^^^^^^^^^^^^^^^^^^^^^^^^^^^^^^^^^^^^^^^^^^^^
  File "/workspaces/abdou.github.io/osint_env/lib/python3.12/site-packages/psycopg2/__init__.py", line 122, in connect
    conn = _connect(dsn, connection_factory=connection_factory, **kwasync)
           ^^^^^^^^^^^^^^^^^^^^^^^^^^^^^^^^^^^^^^^^^^^^^^^^^^^^^^^^^^^^^^^
psycopg2.OperationalError: connection to server at "localhost" (::1), port 5432 failed: FATAL:  password authentication failed for user "osint_user"


The above exception was the direct cause of the following exception:

Traceback (most recent call last):
  File "/workspaces/abdou.github.io/osint_env/bin/uvicorn", line 8, in <module>
    sys.exit(main())
             ^^^^^^
  File "/workspaces/abdou.github.io/osint_env/lib/python3.12/site-packages/click/core.py", line 1442, in __call__
    return self.main(*args, **kwargs)
           ^^^^^^^^^^^^^^^^^^^^^^^^^^
  File "/workspaces/abdou.github.io/osint_env/lib/python3.12/site-packages/click/core.py", line 1363, in main
    rv = self.invoke(ctx)
         ^^^^^^^^^^^^^^^^
  File "/workspaces/abdou.github.io/osint_env/lib/python3.12/site-packages/click/core.py", line 1226, in invoke
    return ctx.invoke(self.callback, **ctx.params)
           ^^^^^^^^^^^^^^^^^^^^^^^^^^^^^^^^^^^^^^^
  File "/workspaces/abdou.github.io/osint_env/lib/python3.12/site-packages/click/core.py", line 794, in invoke
    return callback(*args, **kwargs)
           ^^^^^^^^^^^^^^^^^^^^^^^^^
  File "/workspaces/abdou.github.io/osint_env/lib/python3.12/site-packages/uvicorn/main.py", line 416, in main
    run(
  File "/workspaces/abdou.github.io/osint_env/lib/python3.12/site-packages/uvicorn/main.py", line 587, in run
    server.run()
  File "/workspaces/abdou.github.io/osint_env/lib/python3.12/site-packages/uvicorn/server.py", line 61, in run
    return asyncio.run(self.serve(sockets=sockets))
           ^^^^^^^^^^^^^^^^^^^^^^^^^^^^^^^^^^^^^^^^
  File "/opt/conda/lib/python3.12/asyncio/runners.py", line 194, in run
    return runner.run(main)
           ^^^^^^^^^^^^^^^^
  File "/opt/conda/lib/python3.12/asyncio/runners.py", line 118, in run
    return self._loop.run_until_complete(task)
           ^^^^^^^^^^^^^^^^^^^^^^^^^^^^^^^^^^^
  File "uvloop/loop.pyx", line 1518, in uvloop.loop.Loop.run_until_complete
  File "/workspaces/abdou.github.io/osint_env/lib/python3.12/site-packages/uvicorn/server.py", line 68, in serve
    config.load()
  File "/workspaces/abdou.github.io/osint_env/lib/python3.12/site-packages/uvicorn/config.py", line 467, in load
    self.loaded_app = import_from_string(self.app)
                      ^^^^^^^^^^^^^^^^^^^^^^^^^^^^
  File "/workspaces/abdou.github.io/osint_env/lib/python3.12/site-packages/uvicorn/importer.py", line 21, in import_from_string
    module = importlib.import_module(module_str)
             ^^^^^^^^^^^^^^^^^^^^^^^^^^^^^^^^^^^
  File "/opt/conda/lib/python3.12/importlib/__init__.py", line 90, in import_module
    return _bootstrap._gcd_import(name[level:], package, level)
           ^^^^^^^^^^^^^^^^^^^^^^^^^^^^^^^^^^^^^^^^^^^^^^^^^^^^
  File "<frozen importlib._bootstrap>", line 1387, in _gcd_import
  File "<frozen importlib._bootstrap>", line 1360, in _find_and_load
  File "<frozen importlib._bootstrap>", line 1331, in _find_and_load_unlocked
  File "<frozen importlib._bootstrap>", line 935, in _load_unlocked
  File "<frozen importlib._bootstrap_external>", line 995, in exec_module
  File "<frozen importlib._bootstrap>", line 488, in _call_with_frames_removed
  File "/workspaces/abdou.github.io/backend/main.py", line 29, in <module>
    Base.metadata.create_all(bind=engine)
  File "/workspaces/abdou.github.io/osint_env/lib/python3.12/site-packages/sqlalchemy/sql/schema.py", line 5828, in create_all
    bind._run_ddl_visitor(
  File "/workspaces/abdou.github.io/osint_env/lib/python3.12/site-packages/sqlalchemy/engine/base.py", line 3242, in _run_ddl_visitor
    with self.begin() as conn:
  File "/opt/conda/lib/python3.12/contextlib.py", line 137, in __enter__
    return next(self.gen)
           ^^^^^^^^^^^^^^
  File "/workspaces/abdou.github.io/osint_env/lib/python3.12/site-packages/sqlalchemy/engine/base.py", line 3232, in begin
    with self.connect() as conn:
         ^^^^^^^^^^^^^^
  File "/workspaces/abdou.github.io/osint_env/lib/python3.12/site-packages/sqlalchemy/engine/base.py", line 3268, in connect
    return self._connection_cls(self)
           ^^^^^^^^^^^^^^^^^^^^^^^^^^
  File "/workspaces/abdou.github.io/osint_env/lib/python3.12/site-packages/sqlalchemy/engine/base.py", line 147, in __init__
    Connection._handle_dbapi_exception_noconnection(
  File "/workspaces/abdou.github.io/osint_env/lib/python3.12/site-packages/sqlalchemy/engine/base.py", line 2430, in _handle_dbapi_exception_noconnection
    raise sqlalchemy_exception.with_traceback(exc_info[2]) from e
  File "/workspaces/abdou.github.io/osint_env/lib/python3.12/site-packages/sqlalchemy/engine/base.py", line 145, in __init__
    self._dbapi_connection = engine.raw_connection()
                             ^^^^^^^^^^^^^^^^^^^^^^^
  File "/workspaces/abdou.github.io/osint_env/lib/python3.12/site-packages/sqlalchemy/engine/base.py", line 3292, in raw_connection
    return self.pool.connect()
           ^^^^^^^^^^^^^^^^^^^
  File "/workspaces/abdou.github.io/osint_env/lib/python3.12/site-packages/sqlalchemy/pool/base.py", line 452, in connect
    return _ConnectionFairy._checkout(self)
           ^^^^^^^^^^^^^^^^^^^^^^^^^^^^^^^^
  File "/workspaces/abdou.github.io/osint_env/lib/python3.12/site-packages/sqlalchemy/pool/base.py", line 1269, in _checkout
    fairy = _ConnectionRecord.checkout(pool)
            ^^^^^^^^^^^^^^^^^^^^^^^^^^^^^^^^
  File "/workspaces/abdou.github.io/osint_env/lib/python3.12/site-packages/sqlalchemy/pool/base.py", line 716, in checkout
    rec = pool._do_get()
          ^^^^^^^^^^^^^^
  File "/workspaces/abdou.github.io/osint_env/lib/python3.12/site-packages/sqlalchemy/pool/impl.py", line 169, in _do_get
    with util.safe_reraise():
  File "/workspaces/abdou.github.io/osint_env/lib/python3.12/site-packages/sqlalchemy/util/langhelpers.py", line 146, in __exit__
    raise exc_value.with_traceback(exc_tb)
  File "/workspaces/abdou.github.io/osint_env/lib/python3.12/site-packages/sqlalchemy/pool/impl.py", line 167, in _do_get
    return self._create_connection()
           ^^^^^^^^^^^^^^^^^^^^^^^^^
  File "/workspaces/abdou.github.io/osint_env/lib/python3.12/site-packages/sqlalchemy/pool/base.py", line 393, in _create_connection
    return _ConnectionRecord(self)
           ^^^^^^^^^^^^^^^^^^^^^^^
  File "/workspaces/abdou.github.io/osint_env/lib/python3.12/site-packages/sqlalchemy/pool/base.py", line 678, in __init__
    self.__connect()
  File "/workspaces/abdou.github.io/osint_env/lib/python3.12/site-packages/sqlalchemy/pool/base.py", line 902, in __connect
    with util.safe_reraise():
  File "/workspaces/abdou.github.io/osint_env/lib/python3.12/site-packages/sqlalchemy/util/langhelpers.py", line 146, in __exit__
    raise exc_value.with_traceback(exc_tb)
  File "/workspaces/abdou.github.io/osint_env/lib/python3.12/site-packages/sqlalchemy/pool/base.py", line 898, in __connect
    self.dbapi_connection = connection = pool._invoke_creator(self)
                                         ^^^^^^^^^^^^^^^^^^^^^^^^^^
  File "/workspaces/abdou.github.io/osint_env/lib/python3.12/site-packages/sqlalchemy/engine/create.py", line 637, in connect
    return dialect.connect(*cargs, **cparams)
           ^^^^^^^^^^^^^^^^^^^^^^^^^^^^^^^^^^
  File "/workspaces/abdou.github.io/osint_env/lib/python3.12/site-packages/sqlalchemy/engine/default.py", line 616, in connect
    return self.loaded_dbapi.connect(*cargs, **cparams)
           ^^^^^^^^^^^^^^^^^^^^^^^^^^^^^^^^^^^^^^^^^^^^
  File "/workspaces/abdou.github.io/osint_env/lib/python3.12/site-packages/psycopg2/__init__.py", line 122, in connect
    conn = _connect(dsn, connection_factory=connection_factory, **kwasync)
           ^^^^^^^^^^^^^^^^^^^^^^^^^^^^^^^^^^^^^^^^^^^^^^^^^^^^^^^^^^^^^^^
sqlalchemy.exc.OperationalError: (psycopg2.OperationalError) connection to server at "localhost" (::1), port 5432 failed: FATAL:  password authentication failed for user "osint_user"

(Background on this error at: https://sqlalche.me/e/20/e3q8)
